Workbook

Sheet Overview
A1: CityShield Parametric Insurance - User Journey & Service Mapping
A3: 1. Application summary
A4: Application | B4: CityShield - parametric (index-based) insurance platform. Policies pay out automatically when a measured weather/environmental index (rainfall, river level, temperature, wind...) in a location zone crosses the threshold captured in the policy, without a traditional loss-adjustment process.
A5: Architecture | B5: Microservices: Spring Boot 4.1 / Spring Cloud 2025.1.3, fully reactive (WebFlux functional routers + R2DBC), Netflix Eureka discovery, Spring Cloud Gateway (WebFlux) as edge, JWT (jjwt) auth, synchronous REST between services via @LoadBalanced WebClient (no message broker).
A6: Frontend | B6: Angular 21 SPA (standalone components, lazy routes) + NgRx 21 store/effects; role-based layouts (Public, Customer, Underwriter, Claims Officer, Admin); HTTP interceptors add Bearer token and refresh on 401; notifications pushed via SSE (EventSource).
A7: Persistence | B7: One embedded H2 file database per service under ~/.cityshield/data (database-per-service); claim evidence files under ~/.cityshield/uploads. Schema from schema.sql on startup.
A8: Roles | B8: ROLE_CUSTOMER, ROLE_UNDERWRITER, ROLE_CLAIMS_OFFICER, ROLE_CLAIMS_REVIEWER (mapped to CLAIMS_OFFICER by gateway), ROLE_ADMIN.
A9: Entry point | B9: Browser -> http://localhost:8080 (API Gateway). Services: Eureka 8761, Auth 8081, Product 8082, Claims 8083, Notification 8085, Trigger 8087, Financial 8088.
A10: Core business loop | B10: Admin configures product + trigger -> Customer quotes and applies -> Underwriter approves -> Customer pays premium -> Measurement/observation breaches threshold -> Trigger event -> automatic claim per matching policy -> Claims officer approves -> Payout created -> Admin disburses -> receipt; notifications + audit at every step.
A12: 2. Key figures (live formulas over the detail sheets)
A13: Backend microservices (business) | B13: =COUNTA(Microservices!A4:A11)-2 -> 6 | C13: Excludes Eureka and Gateway rows
A14: Total REST endpoints | B14: =COUNTA('API Endpoints'!A4:A399) -> 207 | C14: All routes parsed from router classes
A15: - Public endpoints | B15: =COUNTIF('API Endpoints'!H4:H399,"Public") -> 11 | C15: No role required by the service
A16: - Secured endpoints | B16: =COUNTIF('API Endpoints'!H4:H399,"Secured") -> 171 | C16: JWT + role
A17: - Internal (service-to-service) | B17: =COUNTIF('API Endpoints'!H4:H399,"Internal") -> 25 | C17: /internal/** paths
A18: Inter-service call paths | B18: =COUNTA('Inter-Service Calls'!A5:A200) -> 33 | C18: Distinct client -> endpoint usages
A19: Scheduled jobs | B19: =COUNTA(#REF!) -> 1 | C19: @Scheduled tasks
A20: Frontend routes | B20: =COUNTA('Frontend Pages'!A5:A200) -> 53 | C20: Angular routes
A21: User journeys | B21: =COUNTA(A25:A44) -> 20 | C21: Detailed in UJ-xx sheets
A23: 3. User journey index (click to open)
A24: Journey ID | B24: Journey | C24: Primary actor(s) | D24: Services involved | E24: Steps | F24: Goal
A25: UJ-01 | B25: Customer Registration, Login & Session | C25: Customer (guest) | D25: Angular SPA, API Gateway, Auth-Svc, Notification-Svc | E25: =COUNTA('UJ-01'!A13:A60) -> 7 | F25: Create an account, sign in, keep the session alive and sign out.
A26: UJ-02 | B26: Browse Product Catalogue (public) | C26: Guest / Customer | D26: Angular SPA, API Gateway (public paths), Product-Svc | E26: =COUNTA('UJ-02'!A13:A60) -> 3 | F26: Discover available parametric insurance products and their trigger rules.
A27: UJ-03 | B27: Customer Profile Management | C27: Customer | D27: Angular SPA, Gateway, Auth-Svc, Notification-Svc | E27: =COUNTA('UJ-03'!A13:A60) -> 3 | F27: Maintain personal details used on policies and claims.
A28: UJ-04 | B28: Get a Quote and Accept It | C28: Customer | D28: Angular SPA, Gateway, Financial-Svc, Product-Svc, Trigger-Svc, Notification-Svc | E28: =COUNTA('UJ-04'!A13:A60) -> 4 | F28: Obtain a priced, time-limited quote for a product, zone, sum insured and term.
A29: UJ-05 | B29: Apply for a Policy (standard product) | C29: Customer | D29: Angular SPA, Gateway, Product-Svc, Financial-Svc, Trigger-Svc, Notification-Svc | E29: =COUNTA('UJ-05'!A13:A60) -> 6 | F29: Submit a policy application on a catalogue product, with or without an accepted quote.
A30: UJ-06 | B30: Custom (Customer-Defined) Parametric Policy | C30: Customer | D30: Angular SPA, Gateway, Product-Svc, Trigger-Svc, Financial-Svc, Notification-Svc | E30: =COUNTA('UJ-06'!A13:A60) -> 3 | F30: Design an own trigger (peril, measurement, threshold, window) and apply for cover on it.
A31: UJ-07 | B31: Underwriting Review (Approve / Reject Policy) | C31: Underwriter (or Admin) | D31: Angular SPA, Gateway, Product-Svc, Trigger-Svc, Notification-Svc | E31: =COUNTA('UJ-07'!A13:A60) -> 5 | F31: Decide on pending policy applications.
A32: UJ-08 | B32: Premium Payment (mock gateway) | C32: Customer, Admin | D32: Angular SPA, Gateway, Financial-Svc, Product-Svc, Notification-Svc | E32: =COUNTA('UJ-08'!A13:A60) -> 6 | F32: Pay the premium for a policy and confirm the payment.
A33: UJ-09 | B33: Policy Servicing (view, certificate, renew, auto-renew, cancel) | C33: Customer | D33: Angular SPA, Gateway, Product-Svc, Trigger-Svc, Financial-Svc, Notification-Svc | E33: =COUNTA('UJ-09'!A13:A60) -> 7 | F33: Manage an existing policy over its life.
A34: UJ-10 | B34: Admin Product Setup & Trigger Threshold Management | C34: Admin | D34: Angular SPA, Gateway, Product-Svc, Trigger-Svc, Financial-Svc, Notification-Svc | E34: =COUNTA('UJ-10'!A13:A60) -> 7 | F34: Create, configure, activate and tune parametric products.
A35: UJ-11 | B35: Admin Reference Data: Zones, Perils, Pricing Rules | C35: Admin | D35: Angular SPA, Gateway, Trigger-Svc, Financial-Svc, Product-Svc, Notification-Svc | E35: =COUNTA('UJ-11'!A13:A60) -> 5 | F35: Maintain the geographic zones, peril catalogue and pricing rules used by products, quotes and triggers.
A36: UJ-12 | B36: Automatic Parametric Claim via Measurement Console (primary flow) | C36: Admin (measurement operator), System, Customer | D36: Angular SPA, Gateway, Trigger-Svc, Product-Svc, Claims-Svc, Notification-Svc | E36: =COUNTA('UJ-12'!A13:A60) -> 7 | F36: Record a live measurement; if it breaches any active policy's captured trigger, create a trigger event and automatic claims for every matching policy.
A37: UJ-13 | B37: Trigger Monitoring, Event Validation & Verification (definition-based flow) | C37: System (monitor), Admin | D37: Trigger-Svc, Product-Svc, Claims-Svc, Notification-Svc, Angular SPA | E37: =COUNTA('UJ-13'!A13:A60) -> 10 | F37: Detect threshold breaches from validated observations and approve them into claims.
A38: UJ-14 | B38: Demo Observation & Threshold Simulation | C38: Admin | D38: Trigger-Svc, Product-Svc, Claims-Svc, Notification-Svc | E38: =COUNTA('UJ-14'!A13:A60) -> 6 | F38: Demonstrate end-to-end: record an observation that crosses the threshold and watch claims appear.
A39: UJ-15 | B39: Customer Manual Claim (exception) with Evidence | C39: Customer | D39: Angular SPA, Gateway, Claims-Svc, Product-Svc, Trigger-Svc, Notification-Svc | E39: =COUNTA('UJ-15'!A13:A60) -> 5 | F39: Claim when a loss occurred but no automatic claim was created (or file a trigger claim manually).
A40: UJ-16 | B40: Claims Officer Review (start, approve -> payout, reject, settle) | C40: Claims Officer (or Admin) | D40: Angular SPA, Gateway, Claims-Svc, Financial-Svc, Notification-Svc | E40: =COUNTA('UJ-16'!A13:A60) -> 8 | F40: Adjudicate submitted claims and trigger payout.
A41: UJ-17 | B41: Payout Disbursement & Receipt | C41: Admin, Customer | D41: Angular SPA, Gateway, Financial-Svc, Trigger-Svc, Product-Svc, Notification-Svc | E41: =COUNTA('UJ-17'!A13:A60) -> 7 | F41: Pay approved claim amounts to customers and provide receipts.
A42: UJ-18 | B42: Notifications, Real-time Push, Preferences & Audit | C42: All roles | D42: Angular SPA, Gateway, Notification-Svc | E42: =COUNTA('UJ-18'!A13:A60) -> 9 | F42: Receive and manage notifications; staff/admin review audit trails.
A43: UJ-19 | B43: Admin User Management & Dashboards | C43: Admin | D43: Angular SPA, Gateway, Auth-Svc, Product-Svc, Financial-Svc | E43: =COUNTA('UJ-19'!A13:A60) -> 6 | F43: Oversee users and platform KPIs.
...

Sheet Microservices
A1: Microservices Catalogue
A3: Service | B3: Eureka name | C3: Port | D3: Responsibility | E3: Gateway routes | F3: Database | G3: Tables | H3: Enums / status values | I3: Routers | J3: Handlers | K3: Services & clients | L3: Schedulers | M3: Calls out to | N3: Called by | O3: # Endpoints | P3: # Public | Q3: # Secured | R3: # Internal
A4: Eureka Server | B4: EUREKA-SERVER | C4: 8761 | D4: Service discovery registry. Every service registers here; the gateway and inter-service WebClients resolve lb://<NAME> through it. | E4: /eureka actuator via /eureka/actuator | F4: None | G4: - | H4: - | I4: - | J4: - | K4: - | L4: - | M4: - | N4: All services (registration / lookup) | O4: =COUNTIFS('API Endpoints'!B$4:B$399,A4) -> 0 | P4: =COUNTIFS('API Endpoints'!B$4:B$399,A4,'API Endpoints'!H$4:H$399,"Public") -> 0 | Q4: =COUNTIFS('API Endpoints'!B$4:B$399,A4,'API Endpoints'!H$4:H$399,"Secured") -> 0 | R4: =COUNTIFS('API Endpoints'!B$4:B$399,A4,'API Endpoints'!H$4:H$399,"Internal") -> 0
A5: API Gateway | B5: API-GATEWAY | C5: 8080 | D5: Single entry point for the Angular SPA. Routes /api/** to services via Eureka load balancing, validates JWTs (GatewayJwtFilter), strips spoofable identity headers and injects X-Gateway-Key + X-Authenticated-User-Id/User/Role/Customer-Id. Proxies each service's actuator under /<svc>/actuator. | E5: (edge) /<svc>/actuator/** | F5: None | G5: - | H5: - | I5: - | J5: - | K5: - | L5: - | M5: All services (routing) | N5: Angular SPA | O5: =COUNTIFS('API Endpoints'!B$4:B$399,A5) -> 0 | P5: =COUNTIFS('API Endpoints'!B$4:B$399,A5,'API Endpoints'!H$4:H$399,"Public") -> 0 | Q5: =COUNTIFS('API Endpoints'!B$4:B$399,A5,'API Endpoints'!H$4:H$399,"Secured") -> 0 | R5: =COUNTIFS('API Endpoints'!B$4:B$399,A5,'API Endpoints'!H$4:H$399,"Internal") -> 0
A6: Auth Service | B6: AUTH-SERVICE | C6: 8081 | D6: Identity & access: registration, login, JWT access/refresh tokens, sessions, email verification, password reset, customer profiles and admin user management. Seeds staff accounts (StaffDataLoader). | E6: /api/auth/**, /api/users/** | F6: H2 file (R2DBC) - ~/.cityshield/data (AuthDatabaseConfig) | G6: addresses, email_verification_tokens, password_reset_tokens, refresh_tokens, roles, sessions, users_credentials, user_profiles, user_roles | H6: CustomerSegment: INDIVIDUAL, FARMER, SMALL_BUSINESS, ENTERPRISE; UserStatus: ACTIVE, SUSPENDED, INACTIVE | I6: AuthRouter, UserRouter | J6: AuthHandler, EmailVerificationHandler, PasswordResetHandler, UserHandler | K6: AuthService, EmailVerificationService, NotificationServiceClient, PasswordResetService, UserProfileService | L6: - | M6: Notification-Svc | N6: Gateway | O6: =COUNTIFS('API Endpoints'!B$4:B$399,A6) -> 18 | P6: =COUNTIFS('API Endpoints'!B$4:B$399,A6,'API Endpoints'!H$4:H$399,"Public") -> 7 | Q6: =COUNTIFS('API Endpoints'!B$4:B$399,A6,'API Endpoints'!H$4:H$399,"Secured") -> 11 | R6: =COUNTIFS('API Endpoints'!B$4:B$399,A6,'API Endpoints'!H$4:H$399,"Internal") -> 0
A7: Product & Policy Service | B7: PRODUCT-SERVICE | C7: 8082 | D7: Insurance product catalogue with parametric trigger configuration, policy applications, underwriting decisions, trigger snapshots, certificates, renewals/expiry, and the verified-event hook that creates automatic claims. | E7: /api/products/**, /api/policies/**, /internal/products/**, /internal/policies/** | F7: H2 file (R2DBC) - productdb | G7: coverages, policies, policy_status_history, policy_trigger_snapshots, products, product_threshold_history | H7: AggregationType: SUM, AVERAGE, MIN, MAX, LATEST; ComparisonOperator: GREATER_THAN, GREATER_THAN_OR_EQUAL, LESS_THAN, LESS_THAN_OR_EQUAL, EQUAL; MeasurementType: RAINFALL, WATER_LEVEL, TEMPERATURE, WIND_SPEED, HUMIDITY, SOIL_MOISTURE, OTHER; MeasurementUnit: MM, CM, METER, CELSIUS, KELVIN, KM_PER_HOUR, METERS_PER_SECOND, PERCENTAGE, OTHER; PerilType: EXCESS_RAINFALL, FLOOD, DROUGHT, EXTREME_TEMPERATURE, CYCLONE, HIGH_WIND, OTHER; PolicyStatus: PENDING, ACTIVE, REJECTED, CANCELLED, EXPIRED; ProductCategory: WEATHER, FLOOD, AGRICULTURE, BUSINESS_INTERRUPTION, TRAVEL, CYCLONE, OTHER; ProductStatus: DRAFT, ACTIVE, INACTIVE, ARCHIVED; TriggerSyncStatus: PENDING, SYNCED, FAILED | I7: InternalPolicyRouter, PolicyLifecycleRouter, PolicyRouter, ProductRouter | J7: InternalPolicyHandler, PolicyHandler, PolicyLifecycleHandler, ProductHandler | K7: NotificationService, NotificationServiceClient, PolicyCertificateService, PolicyService, ProductService, ClaimsServiceClient, FinancialServiceClient, TriggerServiceClient | L7: PolicyExpiryScheduler, PolicyRenewalScheduler (config pkg) | M7: Trigger-Svc, Financial-Svc, Claims-Svc, Notification-Svc | N7: Gateway, Trigger-Svc, Financial-Svc, Claims-Svc | O7: =COUNTIFS('API Endpoints'!B$4:B$399,A7) -> 38 | P7: =COUNTIFS('API Endpoints'!B$4:B$399,A7,'API Endpoints'!H$4:H$399,"Public") -> 4 | Q7: =COUNTIFS('API Endpoints'!B$4:B$399,A7,'API Endpoints'!H$4:H$399,"Secured") -> 27 | R7: =COUNTIFS('API Endpoints'!B$4:B$399,A7,'API Endpoints'!H$4:H$399,"Internal") -> 7
A8: Claims Service | B8: CLAIMS-SERVICE | C8: 8083 | D8: Claims lifecycle: automatic (trigger) and manual-exception claims, evidence documents, officer review (start/approve/reject/settle), timeline; requests payouts on approval. | E8: /api/claims/** | F8: H2 file (R2DBC) - claimsdb (+ uploads dir ~/.cityshield/uploads) | G8: claims, claim_documents, claim_timeline | H8: ClaimSource: AUTO_TRIGGERED, MANUAL_EXCEPTION; ClaimStatus: SUBMITTED, UNDER_REVIEW, APPROVED, SETTLED, REJECTED, CANCELLED; TriggerDetectionStatus: DETECTED, NOT_DETECTED, UNDER_INVESTIGATION, CONFIRMED_MANUALLY, NOT_CONFIRMED | I8: ClaimDocumentRouter, ClaimRouter | J8: ClaimDocumentHandler, ClaimHandler | K8: ClaimDocumentService, ClaimService, FinancialServiceClient, NotificationService, NotificationServiceClient, TriggerEligibilityClient | L8: - | M8: Product-Svc, Trigger-Svc, Financial-Svc, Notification-Svc | N8: Gateway, Product-Svc, Trigger-Svc, Financial-Svc | O8: =COUNTIFS('API Endpoints'!B$4:B$399,A8) -> 25 | P8: =COUNTIFS('API Endpoints'!B$4:B$399,A8,'API Endpoints'!H$4:H$399,"Public") -> 0 | Q8: =COUNTIFS('API Endpoints'!B$4:B$399,A8,'API Endpoints'!H$4:H$399,"Secured") -> 22 | R8: =COUNTIFS('API Endpoints'!B$4:B$399,A8,'API Endpoints'!H$4:H$399,"Internal") -> 3
A9: Trigger Service | B9: TRIGGER-SERVICE | C9: 8087 | D9: Parametric engine: location zones, perils, trigger definitions, observations & validation, evaluations, monitor scans, trigger events (detect/validate/verify/process), current measurements, policy eligibility, demo feed/simulation. | E9: /api/triggers/** | F9: H2 file (R2DBC) - triggerdb | G9: current_measurements, idempotency_records, location_zones, monitor_checkpoints, monitor_runs, observations, perils, trigger_definitions, trigger_evaluations, trigger_events | H9: AggregationType: SUM, AVERAGE, MINIMUM, MAXIMUM, LATEST; ComparisonOperator: GREATER_THAN, GREATER_THAN_OR_EQUAL, LESS_THAN, LESS_THAN_OR_EQUAL, EQUAL; LocationZoneStatus: ACTIVE, INACTIVE, ARCHIVED; MeasurementType: RAINFALL, TEMPERATURE, WIND_SPEED, HUMIDITY, RIVER_LEVEL, SOIL_MOISTURE, OTHER; MeasurementUnit: MM, CM, CELSIUS, KELVIN, KM_PER_HOUR, METERS_PER_SECOND, PERCENTAGE, METER, OTHER; MonitorRunStatus: RUNNING, COMPLETED, FAILED; ObservationSource: MOCK, MANUAL, WEATHER_API, SENSOR; ObservationStatus: RECEIVED, VALIDATED, REJECTED; PerilStatus: ACTIVE, INACTIVE, ARCHIVED; TriggerDefinitionStatus: DRAFT, ACTIVE, INACTIVE, ARCHIVED; TriggerEvaluationResult: MATCHED, NOT_MATCHED, INSUFFICIENT_OBSERVATIONS; TriggerEventStatus: DETECTED, UNDER_VALIDATION, VERIFIED, REJECTED, PROCESSED | I9: DemoObservationRouter, DemoSimulationRouter, LocationZoneRouter, MeasurementRouter, MonitorRunRouter, ObservationRouter, ObservationValidationRouter, PerilRouter, PolicyTriggerEligibilityRouter, TriggerDefinitionRouter, TriggerEvaluationRouter, TriggerEventRouter, ZoneMeasurementRouter | J9: DemoObservationHandler, DemoSimulationHandler, LocationZoneHandler, MeasurementHandler, MonitorRunHandler, ObservationHandler, ObservationValidationHandler, PerilHandler, PolicyTriggerEligibilityHandler, TriggerDefinitionHandler, TriggerEvaluationHandler, TriggerEventHandler | K9: DemoObservationService, DemoSimulationService, IdempotencyService, LocationZoneService, MeasurementService, MonitorRunService, NotificationService, NotificationServiceClient, ObservationService, ObservationValidationService, PerilService, PolicyTriggerEligibilityService, ProductTriggerSyncService, TriggerDefinitionService, TriggerEvaluationService, TriggerEventService, ZoneMeasurementService, ClaimsServiceClient, InternalNotificationClient, ProductTriggerClient | L9: MonitorRunService.runScheduledScan, DemoObservationGenerator | M9: Product-Svc, Claims-Svc, Notification-Svc | N9: Gateway, Product-Svc, Financial-Svc, Claims-Svc | O9: =COUNTIFS('API Endpoints'!B$4:B$399,A9) -> 63 | P9: =COUNTIFS('API Endpoints'!B$4:B$399,A9,'API Endpoints'!H$4:H$399,"Public") -> 0 | Q9: =COUNTIFS('API Endpoints'!B$4:B$399,A9,'API Endpoints'!H$4:H$399,"Secured") -> 56 | R9: =COUNTIFS('API Endpoints'!B$4:B$399,A9,'API Endpoints'!H$4:H$399,"Internal") -> 7
A10: Financial Service | B10: FINANCIAL-SERVICE | C10: 8088 | D10: Money: pricing rules, quotes, premium calculation, payments (mock gateway), payouts, receipts, financial ledger, reconciliation, reminders and retries, admin metrics. | E10: /api/financial/** | F10: H2 file (R2DBC) - financialdb | G10: financial_transactions, payments, payouts, pricing_rules, quotes, reconciliation_records | H10: PaymentMethod: MOCK_CARD, MOCK_BANK_TRANSFER, MOCK_UPI; PaymentStatus: PENDING, SUCCESS, FAILED, REFUNDED; PayoutStatus: PENDING, PROCESSING, SUCCESS, FAILED; PricingRuleStatus: DRAFT, ACTIVE, INACTIVE, ARCHIVED; QuoteStatus: CREATED, ACCEPTED, EXPIRED, CANCELLED, CONSUMED | I10: FinancialRouter, PayoutReceiptRouter | J10: MetricsHandler, PaymentHandler, PayoutHandler, PayoutReceiptHandler, PricingRuleHandler, QuoteHandler | K10: ClaimsServiceClient, DefaultPricingRuleProvisioner, FinancialTransactionService, MetricsService, NotificationService, NotificationServiceClient, PaymentService, PayoutReceiptService, PayoutService, PricingRuleService, ProductServiceClient, QuoteService, TriggerServiceClient | L10: DefaultPricingRuleScheduler, PaymentRetryScheduler, PayoutRetryScheduler, PremiumReminderScheduler, ReconciliationScheduler | M10: Product-Svc, Trigger-Svc, Claims-Svc, Notification-Svc | N10: Gateway, Product-Svc, Claims-Svc | O10: =COUNTIFS('API Endpoints'!B$4:B$399,A10) -> 36 | P10: =COUNTIFS('API Endpoints'!B$4:B$399,A10,'API Endpoints'!H$4:H$399,"Public") -> 0 | Q10: =COUNTIFS('API Endpoints'!B$4:B$399,A10,'API Endpoints'!H$4:H$399,"Secured") -> 30 | R10: =COUNTIFS('API Endpoints'!B$4:B$399,A10,'API Endpoints'!H$4:H$399,"Internal") -> 6
A11: Notification Service | B11: NOTIFICATION-SERVICE | C11: 8085 | D11: In-app notifications (SSE live stream), templates, preferences, delivery attempts and the central audit-event log used by every service. | E11: /api/notifications/** | F11: H2 file (R2DBC) - notificationdb | G11: audit_events, default_templates, delivery_attempts, notifications, notification_preferences, notification_templates | H11: DeliveryChannel: IN_APP; DeliveryStatus: CREATED; NotificationType: POLICY_SUBMITTED, POLICY_APPROVED, POLICY_REJECTED, POLICY_CANCELLED, POLICY_EXPIRED, POLICY_RENEWAL_DUE, POLICY_DOCUMENT_REQUESTED, PRODUCT_CREATED, PRODUCT_UPDATED, CLAIM_SUBMITTED, CLAIM_UNDER_REVIEW, CLAIM_APPROVED, CLAIM_REJECTED, CLAIM_CANCELLED, CLAIM_SETTLED, MANUAL_CLAIM_SUBMITTED, MANUAL_CLAIM_INVESTIGATION_STARTED, MANUAL_CLAIM_INVESTIGATION_COMPLETED, AUTOMATIC_CLAIM_CREATED, CLAIM_DOCUMENT_REQUESTED, CLAIM_REMINDER, CLAIM_ESCALATED, CLAIM_PAYMENT_INITIATED, TRIGGER_DETECTED, TRIGGER_VERIFIED, TRIGGER_REJECTED, TRIGGER_PROCESSED, THRESHOLD_APPROACHING, TRIGGER_THRESHOLD_EXCEEDED, TRIGGER_EVENT_DETECTED, TRIGGER_EVENT_VERIFIED, TRIGGER_EVENT_REJECTED, MANUAL_TRIGGER_CONFIRMED, MANUAL_TRIGGER_NOT_CONFIRMED, PARAMETRIC_COVERAGE_TRIGGERED, OBSERVATION_CREATED, PERIL_CREATED, TRIGGER_DEFINITION_CREATED, LOCATION_ZONE_CREATED, PAYMENT_SUCCESS, PAYMENT_FAILED, PAYMENT_PENDING, PAYMENT_RETRY, PAYMENT_REFUNDED, PAYOUT_PROCESSED, PAYOUT_INITIATED, PAYOUT_SUCCESS, PAYOUT_FAILED, PAYOUT_PENDING, PAYOUT_RETRY, QUOTE_CREATED, QUOTE_EXPIRED, QUOTE_CONSUMED, PREMIUM_DUE, PREMIUM_OVERDUE, REFUND_PROCESSED, REFUND_FAILED, RECONCILIATION_COMPLETED, RECONCILIATION_DISCREPANCY, PRICING_RULE_CREATED, PRICING_RULE_UPDATED, GENERAL; RelatedEntityType: POLICY, CLAIM, TRIGGER_EVENT, PAYMENT, PAYOUT, QUOTE, PRICING_RULE, RECONCILIATION, USER, PRODUCT | I11: NotificationRouter | J11: AuditEventHandler, DeliveryAttemptHandler, NotificationHandler, NotificationPreferenceHandler, NotificationTemplateHandler | K11: AuditEventService, DeliveryAttemptService, EmailDeliveryService, NotificationDeliveryService, NotificationPreferenceService, NotificationScheduler, NotificationService, NotificationStream, NotificationTemplateService, SmsDeliveryService | L11: NotificationScheduler | M11: - (leaf service) | N11: Gateway, all business services | O11: =COUNTIFS('API Endpoints'!B$4:B$399,A11) -> 27 | P11: =COUNTIFS('API Endpoints'!B$4:B$399,A11,'API Endpoints'!H$4:H$399,"Public") -> 0 | Q11: =COUNTIFS('API Endpoints'!B$4:B$399,A11,'API Endpoints'!H$4:H$399,"Secured") -> 25 | R11: =COUNTIFS('API Endpoints'!B$4:B$399,A11,'API Endpoints'!H$4:H$399,"Internal") -> 2
A12: Total | O12: =SUM(O4:O11) -> 207 | P12: =SUM(P4:P11) -> 11 | Q12: =SUM(Q4:Q11) -> 171 | R12: =SUM(R4:R11) -> 25

Sheet API Endpoints
A1: API Endpoint Catalogue (all services)
A3: ID | B3: Service | C3: Eureka name | D3: Router | E3: HTTP | F3: Path | G3: Consumes | H3: Scope | I3: Allowed roles | J3: Gateway / access path | K3: Handler method | L3: Delegates to (service methods) | M3: Business description & rules | N3: Downstream calls / side effects (notifications, audit, DB) | O3: Called from SPA (Angular service.method) | P3: SPA pages (routes)
A4: EP-001 | B4: Auth Service | C4: AUTH-SERVICE | D4: AuthRouter | E4: POST | F4: /api/auth/register | G4: application/json | H4: Public | I4: PUBLIC | J4: Public (no JWT) | K4: AuthHandler.register() | L4: AuthService.register() | M4: Register a new customer account. Normalises email, rejects duplicates, assigns ROLE_CUSTOMER, creates user_credentials + user_roles + initial user_profile, issues access/refresh JWTs and a session. | N4: DB: users_credentials, user_roles, user_profiles, sessions, refresh_tokens | Notification-Svc POST /internal/audit-events (USER_REGISTERED) | O4: AuthService.register | P4: /register
A5: EP-002 | B5: Auth Service | C5: AUTH-SERVICE | D5: AuthRouter | E5: POST | F5: /api/auth/login | G5: application/json | H5: Public | I5: PUBLIC | J5: Public (no JWT) | K5: AuthHandler.login() | L5: AuthService.login() | M5: Authenticate with email + password (BCrypt). Validates user status is ACTIVE, creates a session (device name + IP) and returns access token (15 min) + refresh token (7 days). | N5: DB: sessions, refresh_tokens | Notification-Svc POST /internal/audit-events (USER_LOGIN) | O5: AuthService.login | P5: /login
A6: EP-003 | B6: Auth Service | C6: AUTH-SERVICE | D6: AuthRouter | E6: POST | F6: /api/auth/refresh | G6: application/json | H6: Public | I6: PUBLIC | J6: Public (no JWT) | K6: AuthHandler.refresh() | L6: AuthService.refresh() | M6: Exchange a valid refresh token for a new access/refresh token pair (token rotation). | N6: DB: refresh_tokens, sessions | O6: AuthService.refresh | P6: -
A7: EP-004 | B7: Auth Service | C7: AUTH-SERVICE | D7: AuthRouter | E7: POST | F7: /api/auth/logout | G7: application/json | H7: Secured | I7: AUTHENTICATED | J7: JWT required (Bearer) | K7: AuthHandler.logout() | L7: AuthService.logout() | M7: Revoke the supplied refresh token and end the current session. | N7: DB: refresh_tokens, sessions | O7: AuthService.logout | P7: -
A8: EP-005 | B8: Auth Service | C8: AUTH-SERVICE | D8: AuthRouter | E8: GET | F8: /api/auth/me | G8: application/json | H8: Secured | I8: AUTHENTICATED | J8: JWT required (Bearer) | K8: AuthHandler.me() | L8: - | M8: Return the signed-in user (id, name, email, role, customerId). Used by the SPA to restore a session on reload. | N8: DB read: users_credentials, user_profiles | O8: AuthService.me | P8: -
A9: EP-006 | B9: Auth Service | C9: AUTH-SERVICE | D9: AuthRouter | E9: GET | F9: /api/auth/sessions | G9: application/json | H9: Secured | I9: AUTHENTICATED | J9: JWT required (Bearer) | K9: AuthHandler.sessions() | L9: AuthService.getSessions() | M9: List the caller's active sessions (device, IP, last seen). | N9: DB read: sessions | O9: AuthService.getSessions | P9: -
A10: EP-007 | B10: Auth Service | C10: AUTH-SERVICE | D10: AuthRouter | E10: DELETE | F10: /api/auth/sessions/{sessionId} | G10: - | H10: Secured | I10: AUTHENTICATED | J10: JWT required (Bearer) | K10: AuthHandler.revokeSession() | L10: AuthService.revokeSession() | M10: Revoke one of the caller's sessions (remote sign-out). | N10: DB: sessions, refresh_tokens | O10: AuthService.revokeSession | P10: -
A11: EP-008 | B11: Auth Service | C11: AUTH-SERVICE | D11: AuthRouter | E11: POST | F11: /api/auth/verify-email | G11: application/json | H11: Public | I11: PUBLIC | J11: JWT required at gateway (service itself permits anonymous) | K11: EmailVerificationHandler.verify() | L11: EmailVerificationService.verify() | M11: Verify an email address with a token (24 h expiry). | N11: DB: email_verification_tokens, users_credentials | O11: (not called by SPA) | P11: -
A12: EP-009 | B12: Auth Service | C12: AUTH-SERVICE | D12: AuthRouter | E12: POST | F12: /api/auth/verify-email/resend | G12: application/json | H12: Secured | I12: AUTHENTICATED | J12: JWT required (Bearer) | K12: EmailVerificationHandler.resend() | L12: EmailVerificationService.generateToken() | M12: Re-issue an email verification token for the signed-in user. | N12: DB: email_verification_tokens | O12: (not called by SPA) | P12: -
A13: EP-010 | B13: Auth Service | C13: AUTH-SERVICE | D13: AuthRouter | E13: POST | F13: /api/auth/verify-email/resend-by-email | G13: application/json | H13: Public | I13: PUBLIC | J13: JWT required at gateway (service itself permits anonymous) | K13: EmailVerificationHandler.resendByEmail() | L13: EmailVerificationService.resendVerification() | M13: Re-issue an email verification token by email address. | N13: DB: email_verification_tokens | O13: (not called by SPA) | P13: -
A14: EP-011 | B14: Auth Service | C14: AUTH-SERVICE | D14: AuthRouter | E14: POST | F14: /api/auth/forgot-password | G14: application/json | H14: Public | I14: PUBLIC | J14: JWT required at gateway (service itself permits anonymous) | K14: PasswordResetHandler.forgotPassword() | L14: PasswordResetService.generateToken() | M14: Start password reset: generate a reset token (1 h expiry). | N14: DB: password_reset_tokens | Notification-Svc POST /internal/audit-events | O14: (not called by SPA) | P14: -
... A210: EP-207 | B210: Trigger Service | C210: TRIGGER-SERVICE | D210: ZoneMeasurementRouter | E210: GET | F210: /api/triggers/measurements/zones | G210: application/json | H210: Secured | I210: AUTHENTICATED | J210: JWT required (Bearer) | K210: ZoneMeasurementService (inline lambda).latestPerZone() | L210: ZoneMeasurementService.latestPerZone() | M210: Latest weather readings per zone for the zone map. | N210: DB read | O210: CurrentMeasurementService.getZoneMeasurements | P210: /admin/zone-map, /customer/zone-map

Sheet Service Methods
A1: Handler, Service, Client & Scheduler Methods
A2: Extracted from public method signatures in each class.
A4: Service | B4: Layer | C4: Class | D4: Method | E4: Signature (return type + parameters) | F4: @Scheduled
A5: Auth Service | B5: Handler (HTTP) | C5: AuthHandler | D5: register | E5: Mono<ServerResponse> register(ServerRequest request) | F5: -
A6: Auth Service | B6: Handler (HTTP) | C6: AuthHandler | D6: login | E6: Mono<ServerResponse> login(ServerRequest request) | F6: -
A7: Auth Service | B7: Handler (HTTP) | C7: AuthHandler | D7: refresh | E7: Mono<ServerResponse> refresh(ServerRequest request) | F7: -
A8: Auth Service | B8: Handler (HTTP) | C8: AuthHandler | D8: logout | E8: Mono<ServerResponse> logout(ServerRequest request) | F8: -
A9: Auth Service | B9: Handler (HTTP) | C9: AuthHandler | D9: me | E9: Mono<ServerResponse> me(ServerRequest request) | F9: -
A10: Auth Service | B10: Handler (HTTP) | C10: AuthHandler | D10: sessions | E10: Mono<ServerResponse> sessions(ServerRequest request) | F10: -
A11: Auth Service | B11: Handler (HTTP) | C11: AuthHandler | D11: revokeSession | E11: Mono<ServerResponse> revokeSession(ServerRequest request) | F11: -
A12: Auth Service | B12: Handler (HTTP) | C12: EmailVerificationHandler | D12: verify | E12: Mono<ServerResponse> verify(ServerRequest request) | F12: -
A13: Auth Service | B13: Handler (HTTP) | C13: EmailVerificationHandler | D13: resend | E13: Mono<ServerResponse> resend(ServerRequest request) | F13: -
A14: Auth Service | B14: Handler (HTTP) | C14: EmailVerificationHandler | D14: resendByEmail | E14: Mono<ServerResponse> resendByEmail(ServerRequest request) | F14: -
A15: Auth Service | B15: Handler (HTTP) | C15: PasswordResetHandler | D15: forgotPassword | E15: Mono<ServerResponse> forgotPassword(ServerRequest request) | F15: -
... A543: Notification Service | B543: Config / Loader / Scheduler | C543: NotificationTemplateDataLoader | D543: run | E543: void run(ApplicationArguments args) | F543: -

Sheet Inter-Service Calls
A1: Synchronous Service-to-Service Calls
A2: All via @LoadBalanced WebClient resolving Eureka names; header X-Gateway-Key sent on every call.
A4: ID | B4: Caller service | C4: Caller class.method | D4: Client method | E4: HTTP | F4: Target URL | G4: Target service | H4: Target handler -> service | I4: Purpose | J4: Failure handling
A5: ISC-01 | B5: Auth | C5: AuthService / PasswordResetService / UserProfileService | D5: NotificationServiceClient.audit() | E5: POST | F5: http://NOTIFICATION-SERVICE/internal/audit-events | G5: Notification | H5: AuditEventHandler.create -> AuditEventService.create() | I5: Audit USER_REGISTERED, USER_LOGIN, PROFILE_UPDATED, password reset, status change | J5: onErrorResume -> ignored
A6: ISC-02 | B6: Product | C6: PolicyService.createApplication (validateQuoteIfPresent) | D6: FinancialServiceClient.validateQuote() | E6: POST | F6: http://FINANCIAL-SERVICE/internal/financial/quotes/{quoteId}/validate | G6: Financial | H6: QuoteHandler.validateInternal -> QuoteService.validateInternal() | I6: Validate quote matches application; returns premium | J6: Error -> application rejected (ValidationException)
A7: ISC-03 | B7: Product | C7: PolicyService.resolvePremium | D7: FinancialServiceClient.calculatePremium() | E7: POST | F7: http://FINANCIAL-SERVICE/internal/financial/pricing/calculate | G7: Financial | H7: QuoteHandler.priceInternal -> QuoteService.priceInternal() | I7: Price application without quote | J7: onErrorResume -> empty -> flat temporary premium
A8: ISC-04 | B8: Product | C8: PolicyService.savePendingApplication (consumeQuoteIfPresent) | D8: FinancialServiceClient.consumeQuote() | E8: PUT | F8: http://FINANCIAL-SERVICE/internal/financial/quotes/{quoteId}/consume | G8: Financial | H8: QuoteHandler.consumeInternal -> QuoteService.consume() | I8: Bind quote to policy (CONSUMED) | J8: Propagates error
A9: ISC-05 | B9: Product | C9: PolicyService.getActiveZones / PolicyHandler.getActiveZones | D9: TriggerServiceClient.getActiveZonesList() / getActiveZones() | E9: GET | F9: http://TRIGGER-SERVICE/internal/triggers/zones/active | G9: Trigger | H9: LocationZoneHandler.getInternalActive -> LocationZoneService.getActiveInternal() | I9: Zones for policy form | J9: -
A10: ISC-06 | B10: Product | C10: PolicyCertificateService.forCustomer / forStaff | D10: TriggerServiceClient.getZoneById() | E10: GET | F10: http://TRIGGER-SERVICE/internal/triggers/zones/{zoneId} | G10: Trigger | H10: LocationZoneHandler.getInternalById -> LocationZoneService.getInternalById() | I10: Zone name on certificate PDF | J10: -
A11: ISC-07 | B11: Product | C11: ProductService.getMeasurementStatus / getPublicMeasurementStatus | D11: TriggerServiceClient.getCurrentMeasurements() | E11: GET | F11: http://TRIGGER-SERVICE/internal/triggers/measurements/current | G11: Trigger | H11: MeasurementHandler.getCurrentMeasurementsInternal -> MeasurementService.getCurrentMeasurements() | I11: Measurement console values | J11: -
A12: ISC-08 | B12: Product | C12: ProductService.createCustomerDefinedProduct / syncTrigger -> syncDefinition | D12: TriggerServiceClient.syncProductDefinition() | E12: PUT | F12: http://TRIGGER-SERVICE/internal/triggers/products/{productId}/definition | G12: Trigger | H12: TriggerDefinitionHandler.syncProductDefinition -> ProductTriggerSyncService.syncProductDefinition() | I12: Mirror product trigger as per-zone trigger definitions | J12: onErrorResume -> product triggerSyncStatus=FAILED
A13: ISC-09 | B13: Product | C13: ProductService.processVerifiedEvent -> fetchAndCreateClaimsForEligiblePolicies | D13: TriggerServiceClient.getPolicyEligibility() | E13: GET | F13: http://TRIGGER-SERVICE/internal/triggers/policy/{policyId}/eligibility | G13: Trigger | H13: PolicyTriggerEligibilityHandler.checkEligibility -> PolicyTriggerEligibilityService.checkEligibility() | I13: Per ACTIVE policy: is it eligible for the verified event? | J13: onErrorResume -> 0 claims for that policy
A14: ISC-10 | B14: Product | C14: ProductService.fetchAndCreateClaimsForEligiblePolicies | D14: ClaimsServiceClient.createInternalClaim() | E14: POST | F14: http://CLAIMS-SERVICE/internal/claims | G14: Claims | H14: ClaimHandler.createInternalClaim -> ClaimService.createInternalClaim() | I14: Create automatic claim for eligible policy | J14: onErrorResume -> 0
A15: ISC-11 | B15: Product | C15: NotificationService (product) | D15: NotificationServiceClient.sendNotification() / sendAuditEvent() | E15: POST | F15: http://NOTIFICATION-SERVICE/internal/notifications | /internal/audit-events | G15: Notification | H15: NotificationHandler.create / AuditEventHandler.create | I15: POLICY_*, PRODUCT_* notifications; audit | J15: onErrorResume -> ignored
... A36: ISC-32 | B36: Financial | C36: NotificationService (financial) + schedulers | D36: NotificationServiceClient.sendNotification() / sendAuditEvent() | E36: POST | F36: http://NOTIFICATION-SERVICE/internal/notifications | /internal/audit-events | G36: Notification | H36: NotificationHandler.create / AuditEventHandler.create | I36: PAYMENT_*, PAYOUT_*, QUOTE_*, PREMIUM_*, RECONCILIATION_*, PRICING_RULE_* | J36: onErrorResume
A39: Dependency matrix (count of call paths: row = caller, column = target)
B40: Caller \ Target | C40: Auth | D40: Product | E40: Claims | F40: Trigger | G40: Financial | H40: Notification
B41: Auth | C41: =COUNTIFS($B$5:$B$36,$B41,$G$5:$G$36,C$40) -> 0 | D41: =COUNTIFS($B$5:$B$36,$B41,$G$5:$G$36,D$40) -> 0 | E41: =COUNTIFS($B$5:$B$36,$B41,$G$5:$G$36,E$40) -> 0 | F41: =COUNTIFS($B$5:$B$36,$B41,$G$5:$G$36,F$40) -> 0 | G41: =COUNTIFS($B$5:$B$36,$B41,$G$5:$G$36,G$40) -> 0 | H41: =COUNTIFS($B$5:$B$36,$B41,$G$5:$G$36,H$40) -> 1
B42: Product | C42: =COUNTIFS($B$5:$B$36,$B42,$G$5:$G$36,C$40) -> 0 | D42: =COUNTIFS($B$5:$B$36,$B42,$G$5:$G$36,D$40) -> 0 | E42: =COUNTIFS($B$5:$B$36,$B42,$G$5:$G$36,E$40) -> 1 | F42: =COUNTIFS($B$5:$B$36,$B42,$G$5:$G$36,F$40) -> 5 | G42: =COUNTIFS($B$5:$B$36,$B42,$G$5:$G$36,G$40) -> 3 | H42: =COUNTIFS($B$5:$B$36,$B42,$G$5:$G$36,H$40) -> 1
B43: Claims | C43: =COUNTIFS($B$5:$B$36,$B43,$G$5:$G$36,C$40) -> 0 | D43: =COUNTIFS($B$5:$B$36,$B43,$G$5:$G$36,D$40) -> 1 | E43: =COUNTIFS($B$5:$B$36,$B43,$G$5:$G$36,E$40) -> 0 | F43: =COUNTIFS($B$5:$B$36,$B43,$G$5:$G$36,F$40) -> 1 | G43: =COUNTIFS($B$5:$B$36,$B43,$G$5:$G$36,G$40) -> 1 | H43: =COUNTIFS($B$5:$B$36,$B43,$G$5:$G$36,H$40) -> 1
B44: Trigger | C44: =COUNTIFS($B$5:$B$36,$B44,$G$5:$G$36,C$40) -> 0 | D44: =COUNTIFS($B$5:$B$36,$B44,$G$5:$G$36,D$40) -> 6 | E44: =COUNTIFS($B$5:$B$36,$B44,$G$5:$G$36,E$40) -> 2 | F44: =COUNTIFS($B$5:$B$36,$B44,$G$5:$G$36,F$40) -> 0 | G44: =COUNTIFS($B$5:$B$36,$B44,$G$5:$G$36,G$40) -> 0 | H44: =COUNTIFS($B$5:$B$36,$B44,$G$5:$G$36,H$40) -> 2
B45: Financial | C45: =COUNTIFS($B$5:$B$36,$B45,$G$5:$G$36,C$40) -> 0 | D45: =COUNTIFS($B$5:$B$36,$B45,$G$5:$G$36,D$40) -> 3 | E45: =COUNTIFS($B$5:$B$36,$B45,$G$5:$G$36,E$40) -> 1 | F45: =COUNTIFS($B$5:$B$36,$B45,$G$5:$G$36,F$40) -> 2 | G45: =COUNTIFS($B$5:$B$36,$B45,$G$5:$G$36,G$40) -> 0 | H45: =COUNTIFS($B$5:$B$36,$B45,$G$5:$G$36,H$40) -> 1
B46: Notification | C46: =COUNTIFS($B$5:$B$36,$B46,$G$5:$G$36,C$40) -> 0 | D46: =COUNTIFS($B$5:$B$36,$B46,$G$5:$G$36,D$40) -> 0 | E46: =COUNTIFS($B$5:$B$36,$B46,$G$5:$G$36,E$40) -> 0 | F46: =COUNTIFS($B$5:$B$36,$B46,$G$5:$G$36,F$40) -> 0 | G46: =COUNTIFS($B$5:$B$36,$B46,$G$5:$G$36,G$40) -> 0 | H46: =COUNTIFS($B$5:$B$36,$B46,$G$5:$G$36,H$40) -> 0

Sheet Data Model
A1: Data Model - Tables & Enumerations per Service
A4: Service | B4: Kind | C4: Table name | D4: Model class | E4: Values
A5: Auth Service | B5: Table | C5: addresses | D5: Address | E5: -
A6: Auth Service | B6: Enum | C6: - | D6: CustomerSegment | E6: INDIVIDUAL, FARMER, SMALL_BUSINESS, ENTERPRISE
A7: Auth Service | B7: Table | C7: email_verification_tokens | D7: EmailVerificationToken | E7: -
A8: Auth Service | B8: Table | C8: password_reset_tokens | D8: PasswordResetToken | E8: -
A9: Auth Service | B9: Table | C9: refresh_tokens | D9: RefreshToken | E9: -
A10: Auth Service | B10: Table | C10: roles | D10: Role | E10: -
A11: Auth Service | B11: Table | C11: sessions | D11: Session | E11: -
A12: Auth Service | B12: Table | C12: users_credentials | D12: UserCredential | E12: -
A13: Auth Service | B13: Table | C13: user_profiles | D13: UserProfile | E13: -
A14: Auth Service | B14: Table | C14: user_roles | D14: UserRole | E14: -
A15: Auth Service | B15: Enum | C15: - | D15: UserStatus | E15: ACTIVE, SUSPENDED, INACTIVE
... A80: Notification Service | B80: Enum | C80: - | D80: RelatedEntityType | E80: POLICY, CLAIM, TRIGGER_EVENT, PAYMENT, PAYOUT, QUOTE, PRICING_RULE, RECONCILIATION, USER, PRODUCT

Sheet Status Lifecycles
A1: Entity Status Lifecycles (state machines enforced in code)
A4: Entity | B4: Service | C4: Transition | D4: Triggered by (endpoint / job) | E4: Actor
A5: Policy | B5: Product | C5: (new) -> PENDING | D5: POST /api/policies, /custom, /{id}/renew, renewal scheduler | E5: Customer / System
A6: Policy | B6: Product | C6: PENDING -> ACTIVE | D6: PUT /api/policies/{id}/approve | E6: Underwriter / Admin
A7: Policy | B7: Product | C7: PENDING -> REJECTED | D7: PUT /api/policies/{id}/reject (reason required) | E7: Underwriter / Admin
A8: Policy | B8: Product | C8: PENDING -> CANCELLED | D8: PUT /api/policies/{id}/cancel | E8: Customer
A9: Policy | B9: Product | C9: ACTIVE -> EXPIRED | D9: PolicyExpiryScheduler | E9: System
A10: Product | B10: Product | C10: (new) -> DRAFT -> ACTIVE <-> INACTIVE -> ARCHIVED | D10: POST /api/products; PUT /{id}/status (ACTIVE needs complete trigger; ARCHIVED needs no open policies); DELETE | E10: Admin
A11: Quote | B11: Financial | C11: (new) -> CREATED | D11: POST /api/financial/quotes | E11: Customer
A12: Quote | B12: Financial | C12: CREATED -> ACCEPTED | D12: PUT /quotes/{id}/accept | E12: Customer
A13: Quote | B13: Financial | C13: ACCEPTED -> CONSUMED | D13: PUT /internal/financial/quotes/{id}/consume (policy application) | E13: Product-Svc
A14: Quote | B14: Financial | C14: CREATED/ACCEPTED -> EXPIRED / CANCELLED | D14: expiry after 7 days on read/validate; PUT /quotes/{id}/cancel | E14: System / Customer
A15: Pricing rule | B15: Financial | C15: DRAFT / ACTIVE / INACTIVE / ARCHIVED | D15: PUT /pricing-rules/{id}/status; DELETE archives | E15: Admin
... A37: Monitor run | B37: Trigger | C37: RUNNING -> COMPLETED | FAILED | D37: MonitorRunService | E37: System

Sheet Frontend Pages
A1: Angular SPA - Routes, Components, Actions & Backend Calls
A2: All secured routes use authGuard + roleGuard. Endpoints resolved from API_ENDPOINTS constants (base http://localhost:8080).
A4: Route | B4: Layout | C4: Role | D4: Component | E4: NgRx actions dispatched | F4: Angular service methods | G4: Backend endpoints called (via gateway)
A5: / | B5: PublicLayout | C5: Public | D5: WelcomeComponent | E5: loadProducts | F5: ProductService.getActiveProducts | G5: GET /api/products
A6: /products | B6: PublicLayout | C6: Public | D6: PublicProductListComponent | E6: loadProducts, loadProductsByCategory | F6: ProductService.getActiveProducts, ProductService.getProductsByCategory | G6: GET /api/products GET /api/products/category/{}
A7: /products/:productId | B7: PublicLayout | C7: Public | D7: PublicProductDetailComponent | E7: loadProduct | F7: ProductService.getProduct | G7: GET /api/products/{}
A8: /login | B8: AuthLayout (guestGuard) | C8: Guest | D8: LoginComponent | E8: login | F8: AuthService.login | G8: POST /api/auth/login
A9: /register | B9: AuthLayout (guestGuard) | C9: Guest | D9: RegisterComponent | E9: register | F9: AuthService.register | G9: POST /api/auth/register
A10: /customer/dashboard | B10: CustomerLayout | C10: CUSTOMER | D10: CustomerDashboardComponent | E10: loadMyClaims, loadMyPayments, loadMyPayouts, loadMyPolicies | F10: ClaimService.getMyClaims, PaymentService.getMyPayments, PayoutService.getMyPayouts, PolicyService.getMyPolicies, ProductService.getMeasurementStatus | G10: GET /api/claims/me GET /api/financial/payments/me GET /api/financial/payouts/me GET /api/policies/me GET /api/products/measurement-status
A11: /customer/profile | B11: CustomerLayout | C11: CUSTOMER | D11: CustomerProfileComponent | E11: updateProfile | F11: - | G11: -
A12: /customer/policies | B12: CustomerLayout | C12: CUSTOMER | D12: CustomerPoliciesComponent | E12: cancelPolicy, loadMyPolicies | F12: PolicyService.cancelPolicy, PolicyService.getMyPolicy, PolicyService.getMyPolicies, ZoneService.getActiveZones | G12: PUT /api/policies/{}/cancel GET /api/policies/{} GET /api/policies/me GET /api/triggers/zones/active
A13: /customer/policies/new | B13: CustomerLayout | C13: CUSTOMER | D13: CustomerPolicyNewComponent | E13: createCustomPolicy, createPolicy, loadProducts | F13: PolicyService.createCustomPolicy, PolicyService.createPolicy, ProductService.getActiveProducts, QuoteService.getQuote, ZoneService.getActiveZones | G13: POST /api/policies/custom POST /api/policies GET /api/products GET /api/financial/quotes/{} GET /api/triggers/zones/active
A14: /customer/policies/:policyId | B14: CustomerLayout | C14: CUSTOMER | D14: CustomerPolicyDetailComponent | E14: cancelPolicy, loadMyPolicy | F14: PolicyService.cancelPolicy, PolicyService.getMyPolicy, PolicyService.downloadCertificate, PolicyService.getPolicySnapshot, PolicyService.renewPolicy, PolicyService.setAutoRenew, ZoneService.getZone | G14: PUT /api/policies/{}/cancel GET /api/policies/{} GET /api/policies/{}/certificate GET /api/policies/{}/snapshot POST /api/policies/{}/renew PUT /api/policies/{}/auto-renew GET /api/triggers/zones/{}
A15: /customer/claims | B15: CustomerLayout | C15: CUSTOMER | D15: CustomerClaimsComponent | E15: cancelClaim, loadMyClaims | F15: ClaimService.cancelClaim, ClaimService.getMyClaim, ClaimService.getMyClaims, ZoneService.getActiveZones | G15: PUT /api/claims/{}/cancel GET /api/claims/{} GET /api/claims/me GET /api/triggers/zones/active
... A57: /admin/activity | B57: AdminLayout | C57: ADMIN | D57: AuditHistoryComponent | E57: - | F57: NotificationService.getAuditEvents, NotificationService.getMyAuditEvents | G57: GET /api/notifications/admin/audit GET /api/notifications/audit/me

Sheet UJ-01
A1: UJ-01 Customer Registration, Login & Session
A2: <- Back to Overview
A4: Actor(s) | C4: Customer (guest)
A5: Goal | C5: Create an account, sign in, keep the session alive and sign out.
A6: Trigger / entry | C6: Guest clicks Register / Login on the public site.
A7: Pre-conditions | C7: Auth-Svc running; ROLE_CUSTOMER seeded; Eureka + Gateway up.
A8: Post-conditions | C8: User has access + refresh JWT stored in browser; session row exists; audit trail recorded.
A9: Services involved | C9: Angular SPA, API Gateway, Auth-Svc, Notification-Svc
A10: Service hop chain | C10: SPA -> Gateway -> AUTH-SERVICE
A12: Step | B12: Actor | C12: UI screen / route (component) | D12: User / system action | E12: Frontend call (NgRx action -> Angular service) | F12: HTTP | G12: Endpoint (via Gateway :8080 unless internal) | H12: Target service | I12: Handler method | J12: Service method(s) | K12: Business rules & validations | L12: Inter-service calls (sync REST) | M12: DB tables touched | N12: Status transition | O12: Notifications / audit | P12: Result / UI outcome
A13: 1 | B13: Customer | C13: /register (RegisterComponent) | D13: Fills name, email, password, phone and submits | E13: register() -> AuthEffects.register$ -> AuthService.register() | F13: POST | G13: /api/auth/register | H13: AUTH-SERVICE :8081 | I13: AuthHandler.register | J13: AuthService.register() | K13: Email normalised & must be unique (409 otherwise); password BCrypt-hashed; role ROLE_CUSTOMER assigned; initial profile created. | L13: -> Notification-Svc POST /internal/audit-events (USER_REGISTERED) | M13: users_credentials, user_roles, user_profiles, sessions, refresh_tokens | N13: User: ACTIVE | O13: Audit USER_REGISTERED | P13: AuthResponse {accessToken, refreshToken, user}; tokens saved by TokenStorageService; redirect to /customer/dashboard
A14: 2 | B14: Customer | C14: /login (LoginComponent) | D14: Enters email + password | E14: login() -> AuthEffects.login$ -> AuthService.login() | F14: POST | G14: /api/auth/login | H14: AUTH-SERVICE | I14: AuthHandler.login | J14: AuthService.login() | K14: Invalid email/password -> 401; SUSPENDED/INACTIVE users blocked; device name + IP captured for the session. | L14: -> Notification-Svc POST /internal/audit-events (USER_LOGIN) | M14: sessions, refresh_tokens | N14: - | O14: Audit USER_LOGIN | P14: JWT (claims: userId, email, role, customerId) stored; roleGuard routes to role dashboard
A15: 3 | B15: SPA | C15: App bootstrap (any page reload) | D15: Restore session | E15: restoreSession() -> AuthService.me() | F15: GET | G15: /api/auth/me | H15: AUTH-SERVICE | I15: AuthHandler.me | J15: AuthService.getCurrentUser() | K15: Gateway validates JWT, injects X-Authenticated-User-Id / Role / Customer-Id + X-Gateway-Key headers. | L15: - | M15: read | N15: - | O15: - | P15: User object in NgRx auth state
A16: 4 | B16: SPA | C16: Any secured call (auth.interceptor) | D16: Access token expired (15 min) -> 401 | E16: refreshToken() -> AuthService.refresh() | F16: POST | G16: /api/auth/refresh | H16: AUTH-SERVICE | I16: AuthHandler.refresh | J16: AuthService.refresh() | K16: Refresh token (7 days) must be valid and not revoked; rotated on use. | L16: - | M16: refresh_tokens, sessions | N16: - | O16: - | P16: New token pair; original request retried
A17: 5 | B17: Customer | C17: Header > Sessions | D17: Views & revokes other devices | E17: AuthService.getSessions() / revokeSession() | F17: GET / DELETE | G17: /api/auth/sessions | /api/auth/sessions/{sessionId} | H17: AUTH-SERVICE | I17: AuthHandler.sessions / revokeSession | J17: AuthService.getSessions() / revokeSession() | K17: Only own sessions. | L17: - | M17: sessions, refresh_tokens | N17: Session: revoked | O17: - | P17: Session list refreshed
A18: 6 | B18: Customer | C18: Header > Logout | D18: Signs out | E18: logout() -> AuthService.logout() | F18: POST | G18: /api/auth/logout | H18: AUTH-SERVICE | I18: AuthHandler.logout | J18: AuthService.logout() | K18: Refresh token revoked. | L18: - | M18: refresh_tokens, sessions | N18: Session: ended | O18: - | P18: Tokens cleared, redirect to /login
A19: 7 | B19: Customer (optional) | C19: Email link / Forgot password | D19: Verifies email / resets password | E19: (no SPA screen - API only) | F19: POST | G19: /api/auth/verify-email | /api/auth/forgot-password | /api/auth/reset-password | H19: AUTH-SERVICE | I19: EmailVerificationHandler.verify / PasswordResetHandler.* | J19: EmailVerificationService.verify() / PasswordResetService.generateToken(), resetPassword() | K19: Verification token 24 h; reset token 1 h. | L19: -> Notification-Svc POST /internal/audit-events | M19: email_verification_tokens, password_reset_tokens, users_credentials | N19: - | O19: Audit | P19: Message response

Sheet UJ-02
A1: UJ-02 Browse Product Catalogue (public)
A2: <- Back to Overview
A4: Actor(s) | C4: Guest / Customer
A5: Goal | C5: Discover available parametric insurance products and their trigger rules.
A6: Trigger / entry | C6: Visitor opens the welcome page or /products.
A7: Pre-conditions | C7: At least one product in ACTIVE status.
A8: Post-conditions | C8: Visitor understands cover, limits and trigger; can proceed to apply.
A9: Services involved | C9: Angular SPA, API Gateway (public paths), Product-Svc
A10: Service hop chain | C10: SPA -> Gateway -> PRODUCT-SERVICE
A12: Step | B12: Actor | C12: UI screen / route (component) | D12: User / system action | E12: Frontend call (NgRx action -> Angular service) | F12: HTTP | G12: Endpoint (via Gateway :8080 unless internal) | H12: Target service | I12: Handler method | J12: Service method(s) | K12: Business rules & validations | L12: Inter-service calls (sync REST) | M12: DB tables touched | N12: Status transition | O12: Notifications / audit | P12: Result / UI outcome
A13: 1 | B13: Guest | C13: / (WelcomeComponent) | D13: Lands on home page | E13: loadProducts() -> ProductService.getActiveProducts() | F13: GET | G13: /api/products | H13: PRODUCT-SERVICE :8082 | I13: ProductHandler.getProducts | J13: ProductService.getActiveProducts() | K13: Public path - gateway skips JWT (GET /api/products, /api/products/{id}, /api/products/category/{c}). | L13: - | M13: read products, coverages | N13: - | O13: - | P13: Featured product cards
A14: 2 | B14: Guest | C14: /products (PublicProductListComponent) | D14: Filters by category | E14: loadProductsByCategory() -> ProductService.getProductsByCategory() | F14: GET | G14: /api/products/category/{category} | H14: PRODUCT-SERVICE | I14: ProductHandler.getByCategory | J14: ProductService.getProductsByCategory() | K14: Category must be a valid ProductCategory enum. | L14: - | M14: read | N14: - | O14: - | P14: Filtered list
A15: 3 | B15: Guest | C15: /products/:productId (PublicProductDetailComponent) | D15: Opens a product | E15: loadProduct() -> ProductService.getProduct() | F15: GET | G15: /api/products/{productId} | H15: PRODUCT-SERVICE | I15: ProductHandler.getProduct | J15: ProductService.getActiveProduct() | K15: Only ACTIVE products visible. | L15: - | M15: read | N15: - | O15: - | P15: Product detail + parametric-trigger-card + trigger-explanation; 'Apply' leads to login / policy form

Sheet UJ-03
A1: UJ-03 Customer Profile Management
A2: <- Back to Overview
A4: Actor(s) | C4: Customer
A5: Goal | C5: Maintain personal details used on policies and claims.
A6: Trigger / entry | C6: Customer opens /customer/profile.
A7: Pre-conditions | C7: Signed in as CUSTOMER.
A8: Post-conditions | C8: Today: profile changes only held in browser state (not persisted). Intended: profile saved via PUT /api/users/me with audit.
A9: Services involved | C9: Angular SPA, Gateway, Auth-Svc, Notification-Svc
A10: Service hop chain | C10: SPA -> Gateway -> AUTH-SERVICE -> AUTH-SERVICE (intended) -> NOTIFICATION-SERVICE
A12: Step | B12: Actor | C12: UI screen / route (component) | D12: User / system action | E12: Frontend call (NgRx action -> Angular service) | F12: HTTP | G12: Endpoint (via Gateway :8080 unless internal) | H12: Target service | I12: Handler method | J12: Service method(s) | K12: Business rules & validations | L12: Inter-service calls (sync REST) | M12: DB tables touched | N12: Status transition | O12: Notifications / audit | P12: Result / UI outcome
A13: 1 | B13: Customer | C13: /customer/profile (CustomerProfileComponent) | D13: Opens profile | E13: Reads user from NgRx auth state (loaded by AuthService.me()) | F13: GET | G13: /api/auth/me | H13: AUTH-SERVICE | I13: AuthHandler.me | J13: AuthService.getCurrentUser() | K13: Authenticated. | L13: - | M13: read users_credentials, user_profiles | N13: - | O13: - | P13: Form pre-filled from auth state
A14: 2 | B14: Customer | C14: /customer/profile | D14: Edits and saves | E14: updateProfile() - reducer only; NO effect / HTTP call (see Findings) | F14: - | G14: (none today) - intended: PUT /api/users/me | H14: AUTH-SERVICE (intended) | I14: UserHandler.saveMyProfile (not reached) | J14: UserProfileService.saveProfile() (not reached) | K14: Backend would enforce CUSTOMER role and field validation (phone, DOB, segment INDIVIDUAL/FARMER/SMALL_BUSINESS/ENTERPRISE). | L14: - | M14: none (would be user_profiles, addresses) | N14: - | O14: - | P14: UI shows updated values until reload; data not persisted
A15: 3 | B15: Customer | C15: /customer/activity (AuditHistoryComponent, scope MINE) | D15: Reviews own activity | E15: loadMyAuditEvents() -> NotificationService.getMyAuditEvents() | F15: GET | G15: /api/notifications/audit/me | H15: NOTIFICATION-SERVICE :8085 | I15: AuditEventHandler.mine | J15: AuditEventService.mine() | K15: Only events where actor = caller. | L15: - | M15: read audit_events | N15: - | O15: - | P15: Activity timeline

Sheet UJ-04
A1: UJ-04 Get a Quote and Accept It
A2: <- Back to Overview
A4: Actor(s) | C4: Customer
A5: Goal | C5: Obtain a priced, time-limited quote for a product, zone, sum insured and term.
A6: Trigger / entry | C6: Customer opens /customer/quotes and requests a quote.
A7: Pre-conditions | C7: Product ACTIVE; zone ACTIVE; an ACTIVE pricing rule exists for product (+zone) - DefaultPricingRuleScheduler provisions one per product.
A8: Post-conditions | C8: Quote in ACCEPTED state, valid 7 days, ready to be used in a policy application.
A9: Services involved | C9: Angular SPA, Gateway, Financial-Svc, Product-Svc, Trigger-Svc, Notification-Svc
A10: Service hop chain | C10: SPA -> Gateway -> PRODUCT -> FINANCIAL-SERVICE
A12: Step | B12: Actor | C12: UI screen / route (component) | D12: User / system action | E12: Frontend call (NgRx action -> Angular service) | F12: HTTP | G12: Endpoint (via Gateway :8080 unless internal) | H12: Target service | I12: Handler method | J12: Service method(s) | K12: Business rules & validations | L12: Inter-service calls (sync REST) | M12: DB tables touched | N12: Status transition | O12: Notifications / audit | P12: Result / UI outcome
A13: 1 | B13: Customer | C13: /customer/quotes (CustomerQuotesComponent) | D13: Opens quotes page | E13: loadProducts(), loadQuotes(), ZoneService.getActiveZones() | F13: GET | G13: /api/products | /api/financial/quotes/me | /api/triggers/zones/active | H13: PRODUCT / FINANCIAL / TRIGGER | I13: ProductHandler.getProducts / QuoteHandler.findMine / LocationZoneHandler.getActive | J13: getActiveProducts() / QuoteService.findMine() / LocationZoneService.getActive() | K13: Stale quotes auto-marked EXPIRED on read. | L13: - | M13: read | N13: - | O13: - | P13: Product & zone pickers, my quotes list
A14: 2 | B14: Customer | C14: /customer/quotes | D14: Selects product, zone, sum insured, term -> 'Get quote' | E14: createQuote() -> QuoteService.createQuote() | F14: POST | G14: /api/financial/quotes | H14: FINANCIAL-SERVICE :8088 | I14: QuoteHandler.create | J14: QuoteService.create() | K14: Customer only; sum insured / term within product min-max; zone must be ACTIVE; applicable rule = ACTIVE rule for product+zone (else product-wide). Premium = max(SI x baseAnnualRate x term/12 x termFactor x locationFactor, minimumPremium). | L14: Financial -> Product-Svc GET /internal/products/{productId}; Financial -> Trigger-Svc GET /internal/triggers/zones/{zoneId}; -> Notification-Svc POST /internal/audit-events (QUOTE_CREATED); -> Notification-Svc POST /internal/notifications (QUOTE_CREATED) | M14: quotes | N14: Quote: CREATED (expiresAt = now + 7 days) | O14: Customer notified QUOTE_CREATED | P14: Quote card with premium breakdown
A15: 3 | B15: Customer | C15: /customer/quotes | D15: Clicks 'Accept' | E15: acceptQuote() -> QuoteService.acceptQuote() | F15: PUT | G15: /api/financial/quotes/{quoteId}/accept | H15: FINANCIAL-SERVICE | I15: QuoteHandler.accept | J15: QuoteService.accept() | K15: Must be caller's quote; 409 if CONSUMED / EXPIRED / CANCELLED; idempotent if already ACCEPTED. | L15: -> Notification-Svc POST /internal/audit-events (QUOTE_ACCEPTED) | M15: quotes | N15: Quote: CREATED -> ACCEPTED | O15: Audit | P15: 'Apply with this quote' button -> /customer/policies/new?quoteId=
A16: 4 | B16: Customer (alt) | C16: /customer/quotes | D16: Clicks 'Cancel' | E16: cancelQuote() -> QuoteService.cancelQuote() | F16: PUT | G16: /api/financial/quotes/{quoteId}/cancel | H16: FINANCIAL-SERVICE | I16: QuoteHandler.cancel | J16: QuoteService.cancel() | K16: Own quote, not CONSUMED. | L16: -> Notification-Svc POST /internal/audit-events | M16: quotes | N16: Quote: -> CANCELLED | O16: Audit | P16: Quote greyed out

Sheet UJ-05
A1: UJ-05 Apply for a Policy (standard product)
A2: <- Back to Overview
A4: Actor(s) | C4: Customer
A5: Goal | C5: Submit a policy application on a catalogue product, with or without an accepted quote.
A6: Trigger / entry | C6: Customer submits the form on /customer/policies/new.
A7: Pre-conditions | C7: Signed in as CUSTOMER; product ACTIVE with complete trigger config; optional ACCEPTED quote.
A8: Post-conditions | C8: Policy PENDING with captured trigger snapshot; quote CONSUMED; underwriters notified.
A9: Services involved | C9: Angular SPA, Gateway, Product-Svc, Financial-Svc, Trigger-Svc, Notification-Svc
A10: Service hop chain | C10: SPA -> Gateway -> PRODUCT -> PRODUCT-SERVICE -> FINANCIAL-SERVICE -> PRODUCT-SERVICE -> NOTIFICATION-SERVICE
A12: Step | B12: Actor | C12: UI screen / route (component) | D12: User / system action | E12: Frontend call (NgRx action -> Angular service) | F12: HTTP | G12: Endpoint (via Gateway :8080 unless internal) | H12: Target service | I12: Handler method | J12: Service method(s) | K12: Business rules & validations | L12: Inter-service calls (sync REST) | M12: DB tables touched | N12: Status transition | O12: Notifications / audit | P12: Result / UI outcome
A13: 1 | B13: Customer | C13: /customer/policies/new (CustomerPolicyNewComponent) | D13: Opens form (optionally from a quote) | E13: loadProducts(); QuoteService.getQuote(quoteId); ZoneService.getActiveZones() | F13: GET | G13: /api/products | /api/financial/quotes/{quoteId} | /api/triggers/zones/active | H13: PRODUCT / FINANCIAL / TRIGGER | I13: ProductHandler.getProducts / QuoteHandler.findById / LocationZoneHandler.getActive | J13: - | K13: Quote pre-fills product, zone, sum insured and term. | L13: - | M13: read | N13: - | O13: - | P13: Application form
A14: 2 | B14: Customer | C14: /customer/policies/new | D14: Submits application | E14: createPolicy() -> PolicyService.createPolicy() | F14: POST | G14: /api/policies | H14: PRODUCT-SERVICE :8082 | I14: PolicyHandler.createPolicy | J14: PolicyService.createPolicy() -> createApplication() | K14: Product must be ACTIVE (404); sum insured & term within limits; 409 if a PENDING application exists for same product; location zone required. | L14: - | M14: - | N14: - | O14: - | P14: (continues below - same request)
